#!/usr/bin/env python3
"""
Verificaci√≥n exhaustiva de que el manejo de errores mantiene
toda su funcionalidad despu√©s de la simplificaci√≥n.
"""

import asyncio
from app.core.security.errors import (
    SecurityError,
    create_network_error,
    create_sandbox_error,
    create_rate_limit_error,
    create_verification_error,
    create_file_error,
    SecurityErrorHandler,
    handle_security_errors
)
from app.core.security.sandbox import SecuritySandbox
from app.core.exceptions import ImageConverterError

def test_error_categories():
    """Test todas las categor√≠as de error funcionan."""
    print("üß™ Testing Error Categories...")
    
    # Test 1: Network errors
    error = create_network_error("dns_blocked", host="evil.com")
    assert error.category == "network"
    assert error.details["reason"] == "dns_blocked"
    assert error.details["host"] == "evil.com"
    assert str(error) == "Network access violation"
    print("‚úÖ Network error category working")
    
    # Test 2: Sandbox errors
    error = create_sandbox_error("memory_violation", used_mb=512, limit_mb=256)
    assert error.category == "sandbox"
    assert error.details["reason"] == "memory_violation"
    assert error.details["used_mb"] == 512
    print("‚úÖ Sandbox error category working")
    
    # Test 3: Rate limit errors
    error = create_rate_limit_error("api_calls", current=101, limit=100)
    assert error.category == "rate_limit"
    assert error.details["limit_type"] == "api_calls"
    assert error.details["current"] == 101
    print("‚úÖ Rate limit error category working")
    
    # Test 4: Verification errors
    error = create_verification_error("network_isolation", status="failed")
    assert error.category == "verification"
    assert error.details["check_type"] == "network_isolation"
    assert error.details["status"] == "failed"
    print("‚úÖ Verification error category working")
    
    # Test 5: File errors
    error = create_file_error("path_traversal", path="../etc/passwd")
    assert error.category == "file"
    assert error.details["operation"] == "path_traversal"
    assert error.details["path"] == "../etc/passwd"
    print("‚úÖ File error category working")
    
    return True


def test_error_handler():
    """Test SecurityErrorHandler maneja todos los casos."""
    print("\nüß™ Testing Security Error Handler...")
    
    handler = SecurityErrorHandler()
    
    # Test 1: Handle SecurityError
    error = create_network_error("blocked")
    result = handler.handle_error(error)
    assert result["error"] == "security_violation"
    assert result["category"] == "network"
    assert result["message"] == "Network access violation"
    print("‚úÖ SecurityError handled correctly")
    
    # Test 2: Handle Python exceptions
    test_cases = [
        (TimeoutError("Timeout"), "sandbox", ["timeout", "async_timeout"]),
        (MemoryError("OOM"), "sandbox", ["memory_limit"]),
        (PermissionError("Denied"), "file", ["permission_denied"]),
        (OSError("Network"), "network", ["system_error"]),
    ]
    
    for exc, expected_category, expected_reasons in test_cases:
        result = handler.handle_error(exc)
        assert result["category"] == expected_category
        assert result["details"]["reason"] in expected_reasons
        actual_reason = result["details"]["reason"]
        print(f"‚úÖ {exc.__class__.__name__} ‚Üí {expected_category}/{actual_reason}")
    
    # Test 3: Unknown errors
    result = handler.handle_error(ValueError("Unknown"))
    assert result["category"] == "unknown"
    assert result["message"] == "Security check failed"
    assert result["details"] == {}
    print("‚úÖ Unknown errors handled safely (no details exposed)")
    
    return True


def test_privacy_preservation():
    """Test que no se filtran datos sensibles."""
    print("\nüß™ Testing Privacy Preservation...")
    
    # Test 1: Filenames not in error messages
    error = create_file_error("access", path="/home/user/secret.jpg")
    # The error message should NOT contain the filename
    assert "/home/user/secret.jpg" not in str(error)
    assert str(error) == "File security violation"
    print("‚úÖ Filenames not exposed in error messages")
    
    # Test 2: Handler sanitizes unknown errors
    handler = SecurityErrorHandler()
    result = handler.handle_error(Exception("User password: 12345"))
    assert "12345" not in result["message"]
    assert "password" not in result["message"]
    assert result["message"] == "Security check failed"
    print("‚úÖ Sensitive data sanitized from unknown errors")
    
    # Test 3: Details are structured, not in message
    error = create_network_error("dns_blocked", host="internal.corp")
    assert "internal.corp" not in str(error)
    assert error.details["host"] == "internal.corp"
    print("‚úÖ Sensitive details kept separate from message")
    
    return True


async def test_decorator():
    """Test @handle_security_errors decorator."""
    print("\nüß™ Testing Error Handling Decorator...")
    
    # Test 1: Passes SecurityError unchanged
    @handle_security_errors
    async def raises_security_error():
        raise create_sandbox_error("test")
    
    try:
        await raises_security_error()
        assert False, "Should have raised"
    except SecurityError as e:
        assert e.category == "sandbox"
        print("‚úÖ SecurityError passed through decorator")
    
    # Test 2: Converts other errors
    @handle_security_errors
    async def raises_timeout():
        raise asyncio.TimeoutError("Took too long")
    
    try:
        await raises_timeout()
        assert False, "Should have raised"
    except SecurityError as e:
        assert e.category == "sandbox"
        assert e.details["reason"] in ["timeout", "async_timeout"]
        print("‚úÖ TimeoutError converted to SecurityError")
    
    # Test 3: Successful execution
    @handle_security_errors
    async def succeeds():
        return "success"
    
    result = await succeeds()
    assert result == "success"
    print("‚úÖ Successful execution not affected")
    
    return True


def test_error_integration():
    """Test errores funcionan con componentes reales."""
    print("\nüß™ Testing Error Integration...")
    
    sandbox = SecuritySandbox()
    
    # Test 1: Path validation errors
    try:
        sandbox.validate_path("../../../etc/passwd")
        assert False, "Should have raised"
    except SecurityError as e:
        assert e.category == "file"
        assert "path_traversal" in str(e.details)
        print("‚úÖ Path validation raises correct error")
    
    # Test 2: Command validation errors  
    try:
        sandbox.validate_command(["rm", "-rf", "/"])
        assert False, "Should have raised"
    except SecurityError as e:
        assert e.category == "sandbox"
        assert "forbidden_command" in str(e.details)
        print("‚úÖ Command validation raises correct error")
    
    # Test 3: File access errors
    try:
        sandbox.validate_file_access("/etc/shadow", "read")
        assert False, "Should have raised"
    except SecurityError as e:
        assert e.category == "file"
        print("‚úÖ File access validation raises correct error")
    
    return True


def test_backwards_compatibility():
    """Test compatibilidad con c√≥digo existente."""
    print("\nüß™ Testing Backwards Compatibility...")
    
    # Test 1: SecurityError is still an Exception
    error = create_network_error("test")
    assert isinstance(error, Exception)
    print("‚úÖ SecurityError is Exception subclass")
    
    # Test 2: Can catch with generic Exception
    try:
        raise create_sandbox_error("test")
    except Exception:
        print("‚úÖ Can catch with Exception")
    
    # Test 3: Error attributes accessible
    error = create_file_error("test", filename="secret.jpg")
    assert hasattr(error, "category")
    assert hasattr(error, "details")
    assert error.details.get("filename") == "secret.jpg"
    print("‚úÖ Error attributes accessible")
    
    return True


async def main():
    """Run all error handling tests."""
    print("üîí VERIFICACI√ìN DE MANEJO DE ERRORES")
    print("=" * 50)
    
    try:
        # Test 1: Categories
        test_error_categories()
        
        # Test 2: Handler
        test_error_handler()
        
        # Test 3: Privacy
        test_privacy_preservation()
        
        # Test 4: Decorator
        await test_decorator()
        
        # Test 5: Integration
        test_error_integration()
        
        # Test 6: Compatibility
        test_backwards_compatibility()
        
        print("\n‚úÖ TODOS LOS TESTS DE MANEJO DE ERRORES PASARON!")
        print("El sistema de errores simplificado mantiene:")
        print("- ‚úÖ Todas las categor√≠as necesarias (network, sandbox, rate_limit, verification, file)")
        print("- ‚úÖ Mapeo autom√°tico de excepciones Python")
        print("- ‚úÖ Privacidad: sin PII en mensajes de error")
        print("- ‚úÖ Decorador funcional para conversi√≥n de errores")
        print("- ‚úÖ Integraci√≥n con todos los componentes")
        print("- ‚úÖ Compatibilidad hacia atr√°s")
        print("\nLa simplificaci√≥n de 60+ c√≥digos a 5 categor√≠as NO perdi√≥ funcionalidad.")
        
    except Exception as e:
        print(f"\n‚ùå TEST FALL√ì: {e}")
        import traceback
        traceback.print_exc()
        return False
    
    return True


if __name__ == "__main__":
    success = asyncio.run(main())
    exit(0 if success else 1)